Workbook

Sheet Data Validation
A3: Row Labels | B3: Count of Claim_ID | D3: Row Labels | E3: Count of Claim_ID
A4: Accident | B4: 743 | D4: Central | E4: 1188
A5: Baggage Loss | B5: 348 | D5: East | E5: 1459
A6: Critical Illness | B6: 726 | D6: North | E6: 1718
A7: Death Benefit | B7: 420 | D7: South | E7: 1763
A8: Disability | B8: 432 | D8: West | E8: 1872
A9: Fire | B9: 425 | D9: Grand Total | E9: 8000
A10: Hospitalisation | B10: 21
A11: Hospitalization | B11: 780
A12: Maturity | B12: 367
A13: Medical Emerg. | B13: 19
A14: Medical Emergency | B14: 330
A15: Outpatient | B15: 758
A16: Property Damage | B16: 404
A17: Property dmg | B17: 18
A18: Theft | B18: 1135
A19: Trip Cancellation | B19: 326
A20: Vehicle Damage | B20: 728
A21: Vehicle dmg | B21: 20
A22: Grand Total | B22: 8000

Sheet claims_raw
A1: Claim_ID | B1: Customer_ID | C1: Policy_ID | D1: Claim_Type | E1: Region | F1: Claim_Amount | G1: Claim_Date | H1: Settlement_Date | I1: Claim_Status | J1: Processing_Days | K1: SLA_Days | L1: Agent_ID | M1: Policy_Type | N1: Workflow | O1: Duplicate_check | P1: Amount_Validation | Q1: Customer_Region_Lookup | R1: Final_Region | S1: Standardized_Claim_Type | T1: SLA_Status | U1: Delay_Days
A2: CLM000001 | B2: CUST00261 | C2: POL02744 | D2: Accident | E2: South | F2: 83890.75 | G2: 45748 | H2: 45757 | I2: Settled | J2: 9 | K2: 10 | L2: AGT013 | M2: Motor | N2: Fast Track | O2: =COUNTIF($A:$A,A2) -> 1 | P2: =IF(F2="","Missing Amount","Valid") -> Valid | Q2: =_xlfn.XLOOKUP(B2,Customers!$A:$A,Customers!$C:$C,"Not Found") -> West | R2: =IF(E2="",Q2,E2) -> South | S2: =IF(D2="Hospitalisation","Hospitalization",IF(D2="Medical Emerg.","Medical Emergency",IF(D2="Property dmg","Property Damage",IF(D2="Vehicle dmg","Vehicle Damage",D2)))) -> Accident | T2: =IF(J2>K2,"SLA Breach","Within SLA") -> Within SLA | U2: =IF(J2>K2,J2-K2,0) -> 0
A3: CLM000002 | B3: CUST01743 | C3: POL03031 | D3: Disability | E3: West | F3: 460193.63 | G3: 45765 | H3: 45785 | I3: Settled | J3: 20 | K3: 20 | L3: AGT009 | M3: Life | N3: Standard | O3: =COUNTIF($A:$A,A3) -> 1 | P3: =IF(F3="","Missing Amount","Valid") -> Valid | Q3: =_xlfn.XLOOKUP(B3,Customers!$A:$A,Customers!$C:$C,"Not Found") -> East | R3: =IF(E3="",Q3,E3) -> West | S3: =IF(D3="Hospitalisation","Hospitalization",IF(D3="Medical Emerg.","Medical Emergency",IF(D3="Property dmg","Property Damage",IF(D3="Vehicle dmg","Vehicle Damage",D3)))) -> Disability | T3: =IF(J3>K3,"SLA Breach","Within SLA") -> Within SLA | U3: =IF(J3>K3,J3-K3,0) -> 0
A4: CLM000003 | B4: CUST01811 | C4: POL00282 | D4: Death Benefit | E4: South | F4: 987323.12 | G4: 45701 | H4: 45718 | I4: Settled | J4: 17 | K4: 20 | L4: AGT040 | M4: Life | N4: Standard | O4: =COUNTIF($A:$A,A4) -> 1 | P4: =IF(F4="","Missing Amount","Valid") -> Valid | Q4: =_xlfn.XLOOKUP(B4,Customers!$A:$A,Customers!$C:$C,"Not Found") -> East | R4: =IF(E4="",Q4,E4) -> South | S4: =IF(D4="Hospitalisation","Hospitalization",IF(D4="Medical Emerg.","Medical Emergency",IF(D4="Property dmg","Property Damage",IF(D4="Vehicle dmg","Vehicle Damage",D4)))) -> Death Benefit | T4: =IF(J4>K4,"SLA Breach","Within SLA") -> Within SLA | U4: =IF(J4>K4,J4-K4,0) -> 0
A5: CLM000004 | B5: CUST01475 | C5: POL00572 | D5: Death Benefit | E5: North | F5: 93726.48 | G5: 45796 | I5: Pending | J5: 24 | K5: 20 | L5: AGT061 | M5: Life | N5: Manual Review | O5: =COUNTIF($A:$A,A5) -> 1 | P5: =IF(F5="","Missing Amount","Valid") -> Valid | Q5: =_xlfn.XLOOKUP(B5,Customers!$A:$A,Customers!$C:$C,"Not Found") -> North | R5: =IF(E5="",Q5,E5) -> North | S5: =IF(D5="Hospitalisation","Hospitalization",IF(D5="Medical Emerg.","Medical Emergency",IF(D5="Property dmg","Property Damage",IF(D5="Vehicle dmg","Vehicle Damage",D5)))) -> Death Benefit | T5: =IF(J5>K5,"SLA Breach","Within SLA") -> SLA Breach | U5: =IF(J5>K5,J5-K5,0) -> 4
A6: CLM000005 | B6: CUST00556 | C6: POL02641 | D6: Theft | E6: North | F6: 124530.61 | G6: 45699 | H6: 45711 | I6: Rejected | J6: 12 | K6: 12 | L6: AGT053 | M6: Home | N6: Standard | O6: =COUNTIF($A:$A,A6) -> 1 | P6: =IF(F6="","Missing Amount","Valid") -> Valid | Q6: =_xlfn.XLOOKUP(B6,Customers!$A:$A,Customers!$C:$C,"Not Found") -> East | R6: =IF(E6="",Q6,E6) -> North | S6: =IF(D6="Hospitalisation","Hospitalization",IF(D6="Medical Emerg.","Medical Emergency",IF(D6="Property dmg","Property Damage",IF(D6="Vehicle dmg","Vehicle Damage",D6)))) -> Theft | T6: =IF(J6>K6,"SLA Breach","Within SLA") -> Within SLA | U6: =IF(J6>K6,J6-K6,0) -> 0
A7: CLM000006 | B7: CUST00712 | C7: POL00974 | D7: Hospitalization | E7: West | F7: 61375.46 | G7: 45671 | H7: 45686 | I7: Settled | J7: 15 | K7: 15 | L7: AGT064 | M7: Health | N7: Fast Track | O7: =COUNTIF($A:$A,A7) -> 1 | P7: =IF(F7="","Missing Amount","Valid") -> Valid | Q7: =_xlfn.XLOOKUP(B7,Customers!$A:$A,Customers!$C:$C,"Not Found") -> West | R7: =IF(E7="",Q7,E7) -> West | S7: =IF(D7="Hospitalisation","Hospitalization",IF(D7="Medical Emerg.","Medical Emergency",IF(D7="Property dmg","Property Damage",IF(D7="Vehicle dmg","Vehicle Damage",D7)))) -> Hospitalization | T7: =IF(J7>K7,"SLA Breach","Within SLA") -> Within SLA | U7: =IF(J7>K7,J7-K7,0) -> 0
A8: CLM000007 | B8: CUST01190 | C8: POL02002 | D8: Critical Illness | E8: South | F8: 82830.72 | G8: 45771 | H8: 45784 | I8: Settled | J8: 13 | K8: 15 | L8: AGT037 | M8: Health | N8: Standard | O8: =COUNTIF($A:$A,A8) -> 1 | P8: =IF(F8="","Missing Amount","Valid") -> Valid | Q8: =_xlfn.XLOOKUP(B8,Customers!$A:$A,Customers!$C:$C,"Not Found") -> South | R8: =IF(E8="",Q8,E8) -> South | S8: =IF(D8="Hospitalisation","Hospitalization",IF(D8="Medical Emerg.","Medical Emergency",IF(D8="Property dmg","Property Damage",IF(D8="Vehicle dmg","Vehicle Damage",D8)))) -> Critical Illness | T8: =IF(J8>K8,"SLA Breach","Within SLA") -> Within SLA | U8: =IF(J8>K8,J8-K8,0) -> 0
A9: CLM000008 | B9: CUST00563 | C9: POL01115 | D9: Hospitalization | E9: West | F9: 87525.1 | G9: 45942 | I9: Under Review | J9: 12 | K9: 15 | L9: AGT071 | M9: Health | N9: Standard | O9: =COUNTIF($A:$A,A9) -> 1 | P9: =IF(F9="","Missing Amount","Valid") -> Valid | Q9: =_xlfn.XLOOKUP(B9,Customers!$A:$A,Customers!$C:$C,"Not Found") -> South | R9: =IF(E9="",Q9,E9) -> West | S9: =IF(D9="Hospitalisation","Hospitalization",IF(D9="Medical Emerg.","Medical Emergency",IF(D9="Property dmg","Property Damage",IF(D9="Vehicle dmg","Vehicle Damage",D9)))) -> Hospitalization | T9: =IF(J9>K9,"SLA Breach","Within SLA") -> Within SLA | U9: =IF(J9>K9,J9-K9,0) -> 0
A10: CLM000009 | B10: CUST02359 | C10: POL00697 | D10: Property Damage | E10: North | F10: 90857.28 | G10: 45982 | H10: 46000 | I10: Settled | J10: 18 | K10: 12 | L10: AGT062 | M10: Home | N10: Standard | O10: =COUNTIF($A:$A,A10) -> 1 | P10: =IF(F10="","Missing Amount","Valid") -> Valid | Q10: =_xlfn.XLOOKUP(B10,Customers!$A:$A,Customers!$C:$C,"Not Found") -> North | R10: =IF(E10="",Q10,E10) -> North | S10: =IF(D10="Hospitalisation","Hospitalization",IF(D10="Medical Emerg.","Medical Emergency",IF(D10="Property dmg","Property Damage",IF(D10="Vehicle dmg","Vehicle Damage",D10)))) -> Property Damage | T10: =IF(J10>K10,"SLA Breach","Within SLA") -> SLA Breach | U10: =IF(J10>K10,J10-K10,0) -> 6
A11: CLM000010 | B11: CUST00688 | C11: POL02000 | D11: Hospitalization | E11: East | F11: 41926.34 | G11: 45946 | H11: 45950 | I11: Settled | J11: 4 | K11: 15 | L11: AGT004 | M11: Health | N11: Fast Track | O11: =COUNTIF($A:$A,A11) -> 1 | P11: =IF(F11="","Missing Amount","Valid") -> Valid | Q11: =_xlfn.XLOOKUP(B11,Customers!$A:$A,Customers!$C:$C,"Not Found") -> Central | R11: =IF(E11="",Q11,E11) -> East | S11: =IF(D11="Hospitalisation","Hospitalization",IF(D11="Medical Emerg.","Medical Emergency",IF(D11="Property dmg","Property Damage",IF(D11="Vehicle dmg","Vehicle Damage",D11)))) -> Hospitalization | T11: =IF(J11>K11,"SLA Breach","Within SLA") -> Within SLA | U11: =IF(J11>K11,J11-K11,0) -> 0
A12: CLM000011 | B12: CUST01734 | C12: POL00658 | D12: Theft | E12: North | F12: 56713.74 | G12: 45977 | H12: 45994 | I12: Settled | J12: 17 | K12: 12 | L12: AGT041 | M12: Home | N12: Manual Review | O12: =COUNTIF($A:$A,A12) -> 1 | P12: =IF(F12="","Missing Amount","Valid") -> Valid | Q12: =_xlfn.XLOOKUP(B12,Customers!$A:$A,Customers!$C:$C,"Not Found") -> West | R12: =IF(E12="",Q12,E12) -> North | S12: =IF(D12="Hospitalisation","Hospitalization",IF(D12="Medical Emerg.","Medical Emergency",IF(D12="Property dmg","Property Damage",IF(D12="Vehicle dmg","Vehicle Damage",D12)))) -> Theft | T12: =IF(J12>K12,"SLA Breach","Within SLA") -> SLA Breach | U12: =IF(J12>K12,J12-K12,0) -> 5
A13: CLM000012 | B13: CUST00945 | C13: POL00437 | D13: Death Benefit | E13: South | F13: 1194437 | G13: 45949 | I13: Pending | J13: 27 | K13: 20 | L13: AGT078 | M13: Life | N13: Manual Review | O13: =COUNTIF($A:$A,A13) -> 1 | P13: =IF(F13="","Missing Amount","Valid") -> Valid | Q13: =_xlfn.XLOOKUP(B13,Customers!$A:$A,Customers!$C:$C,"Not Found") -> Central | R13: =IF(E13="",Q13,E13) -> South | S13: =IF(D13="Hospitalisation","Hospitalization",IF(D13="Medical Emerg.","Medical Emergency",IF(D13="Property dmg","Property Damage",IF(D13="Vehicle dmg","Vehicle Damage",D13)))) -> Death Benefit | T13: =IF(J13>K13,"SLA Breach","Within SLA") -> SLA Breach | U13: =IF(J13>K13,J13-K13,0) -> 7
A14: CLM000013 | B14: CUST01458 | C14: POL01698 | D14: Accident | E14: East | F14: 26479.35 | G14: 45876 | H14: 45901 | I14: Settled | J14: 25 | K14: 10 | L14: AGT059 | M14: Motor | N14: Fraud Review | O14: =COUNTIF($A:$A,A14) -> 1 | P14: =IF(F14="","Missing Amount","Valid") -> Valid | Q14: =_xlfn.XLOOKUP(B14,Customers!$A:$A,Customers!$C:$C,"Not Found") -> Central | R14: =IF(E14="",Q14,E14) -> East | S14: =IF(D14="Hospitalisation","Hospitalization",IF(D14="Medical Emerg.","Medical Emergency",IF(D14="Property dmg","Property Damage",IF(D14="Vehicle dmg","Vehicle Damage",D14)))) -> Accident | T14: =IF(J14>K14,"SLA Breach","Within SLA") -> SLA Breach | U14: =IF(J14>K14,J14-K14,0) -> 15
A15: CLM000014 | B15: CUST01843 | C15: POL00619 | D15: Baggage Loss | E15: North | F15: 66587.41 | G15: 45718 | I15: Pending | J15: 8 | K15: 7 | L15: AGT066 | M15: Travel | N15: Standard | O15: =COUNTIF($A:$A,A15) -> 1 | P15: =IF(F15="","Missing Amount","Valid") -> Valid | Q15: =_xlfn.XLOOKUP(B15,Customers!$A:$A,Customers!$C:$C,"Not Found") -> East | R15: =IF(E15="",Q15,E15) -> North | S15: =IF(D15="Hospitalisation","Hospitalization",IF(D15="Medical Emerg.","Medical Emergency",IF(D15="Property dmg","Property Damage",IF(D15="Vehicle dmg","Vehicle Damage",D15)))) -> Baggage Loss | T15: =IF(J15>K15,"SLA Breach","Within SLA") -> SLA Breach | U15: =IF(J15>K15,J15-K15,0) -> 1
A16: CLM000015 | B16: CUST01312 | C16: POL00616 | D16: Theft | E16: South | F16: 33168.94 | G16: 45928 | H16: 45937 | I16: Settled | J16: 9 | K16: 10 | L16: AGT058 | M16: Motor | N16: Fast Track | O16: =COUNTIF($A:$A,A16) -> 1 | P16: =IF(F16="","Missing Amount","Valid") -> Valid | Q16: =_xlfn.XLOOKUP(B16,Customers!$A:$A,Customers!$C:$C,"Not Found") -> North | R16: =IF(E16="",Q16,E16) -> South | S16: =IF(D16="Hospitalisation","Hospitalization",IF(D16="Medical Emerg.","Medical Emergency",IF(D16="Property dmg","Property Damage",IF(D16="Vehicle dmg","Vehicle Damage",D16)))) -> Theft | T16: =IF(J16>K16,"SLA Breach","Within SLA") -> Within SLA | U16: =IF(J16>K16,J16-K16,0) -> 0
A17: CLM000016 | B17: CUST02196 | C17: POL02498 | D17: Maturity | E17: East | F17: 319188.49 | G17: 45984 | H17: 46004 | I17: Settled | J17: 20 | K17: 20 | L17: AGT049 | M17: Life | N17: Standard | O17: =COUNTIF($A:$A,A17) -> 1 | P17: =IF(F17="","Missing Amount","Valid") -> Valid | Q17: =_xlfn.XLOOKUP(B17,Customers!$A:$A,Customers!$C:$C,"Not Found") -> West | R17: =IF(E17="",Q17,E17) -> East | S17: =IF(D17="Hospitalisation","Hospitalization",IF(D17="Medical Emerg.","Medical Emergency",IF(D17="Property dmg","Property Damage",IF(D17="Vehicle dmg","Vehicle Damage",D17)))) -> Maturity | T17: =IF(J17>K17,"SLA Breach","Within SLA") -> Within SLA | U17: =IF(J17>K17,J17-K17,0) -> 0
A18: CLM000017 | B18: CUST01665 | C18: POL01692 | D18: Accident | E18: West | F18: 233621.8 | G18: 45823 | I18: Pending | J18: 28 | K18: 10 | L18: AGT027 | M18: Motor | N18: Fraud Review | O18: =COUNTIF($A:$A,A18) -> 1 | P18: =IF(F18="","Missing Amount","Valid") -> Valid | Q18: =_xlfn.XLOOKUP(B18,Customers!$A:$A,Customers!$C:$C,"Not Found") -> West | R18: =IF(E18="",Q18,E18) -> West | S18: =IF(D18="Hospitalisation","Hospitalization",IF(D18="Medical Emerg.","Medical Emergency",IF(D18="Property dmg","Property Damage",IF(D18="Vehicle dmg","Vehicle Damage",D18)))) -> Accident | T18: =IF(J18>K18,"SLA Breach","Within SLA") -> SLA Breach | U18: =IF(J18>K18,J18-K18,0) -> 18
A19: CLM000018 | B19: CUST00338 | C19: POL01735 | D19: Fire | E19: West | F19: 184402.86 | G19: 45878 | I19: Under Review | J19: 12 | K19: 12 | L19: AGT006 | M19: Home | N19: Manual Review | O19: =COUNTIF($A:$A,A19) -> 1 | P19: =IF(F19="","Missing Amount","Valid") -> Valid | Q19: =_xlfn.XLOOKUP(B19,Customers!$A:$A,Customers!$C:$C,"Not Found") -> South | R19: =IF(E19="",Q19,E19) -> West | S19: =IF(D19="Hospitalisation","Hospitalization",IF(D19="Medical Emerg.","Medical Emergency",IF(D19="Property dmg","Property Damage",IF(D19="Vehicle dmg","Vehicle Damage",D19)))) -> Fire | T19: =IF(J19>K19,"SLA Breach","Within SLA") -> Within SLA | U19: =IF(J19>K19,J19-K19,0) -> 0
A20: CLM000019 | B20: CUST00294 | C20: POL00459 | D20: Medical Emergency | E20: North | F20: 11780.23 | G20: 45786 | I20: Pending | J20: 1 | K20: 7 | L20: AGT025 | M20: Travel | N20: Standard | O20: =COUNTIF($A:$A,A20) -> 1 | P20: =IF(F20="","Missing Amount","Valid") -> Valid | Q20: =_xlfn.XLOOKUP(B20,Customers!$A:$A,Customers!$C:$C,"Not Found") -> Central | R20: =IF(E20="",Q20,E20) -> North | S20: =IF(D20="Hospitalisation","Hospitalization",IF(D20="Medical Emerg.","Medical Emergency",IF(D20="Property dmg","Property Damage",IF(D20="Vehicle dmg","Vehicle Damage",D20)))) -> Medical Emergency | T20: =IF(J20>K20,"SLA Breach","Within SLA") -> Within SLA | U20: =IF(J20>K20,J20-K20,0) -> 0
A21: CLM000020 | B21: CUST01888 | C21: POL00514 | D21: Medical Emergency | E21: North | F21: 24098.03 | G21: 45856 | H21: 45876 | I21: Settled | J21: 20 | K21: 7 | L21: AGT020 | M21: Travel | N21: Fraud Review | O21: =COUNTIF($A:$A,A21) -> 1 | P21: =IF(F21="","Missing Amount","Valid") -> Valid | Q21: =_xlfn.XLOOKUP(B21,Customers!$A:$A,Customers!$C:$C,"Not Found") -> North | R21: =IF(E21="",Q21,E21) -> North | S21: =IF(D21="Hospitalisation","Hospitalization",IF(D21="Medical Emerg.","Medical Emergency",IF(D21="Property dmg","Property Damage",IF(D21="Vehicle dmg","Vehicle Damage",D21)))) -> Medical Emergency | T21: =IF(J21>K21,"SLA Breach","Within SLA") -> SLA Breach | U21: =IF(J21>K21,J21-K21,0) -> 13
A22: CLM000021 | B22: CUST01725 | C22: POL01251 | D22: Theft | E22: South | F22: 63916.2 | G22: 45665 | H22: 45679 | I22: Settled | J22: 14 | K22: 10 | L22: AGT058 | M22: Motor | N22: Manual Review | O22: =COUNTIF($A:$A,A22) -> 1 | P22: =IF(F22="","Missing Amount","Valid") -> Valid | Q22: =_xlfn.XLOOKUP(B22,Customers!$A:$A,Customers!$C:$C,"Not Found") -> North | R22: =IF(E22="",Q22,E22) -> South | S22: =IF(D22="Hospitalisation","Hospitalization",IF(D22="Medical Emerg.","Medical Emergency",IF(D22="Property dmg","Property Damage",IF(D22="Vehicle dmg","Vehicle Damage",D22)))) -> Theft | T22: =IF(J22>K22,"SLA Breach","Within SLA") -> SLA Breach | U22: =IF(J22>K22,J22-K22,0) -> 4
A23: CLM000022 | B23: CUST01395 | C23: POL01243 | D23: Property Damage | E23: South | F23: 214938.27 | G23: 45899 | H23: 45917 | I23: Settled | J23: 18 | K23: 12 | L23: AGT028 | M23: Home | N23: Standard | O23: =COUNTIF($A:$A,A23) -> 1 | P23: =IF(F23="","Missing Amount","Valid") -> Valid | Q23: =_xlfn.XLOOKUP(B23,Customers!$A:$A,Customers!$C:$C,"Not Found") -> Central | R23: =IF(E23="",Q23,E23) -> South | S23: =IF(D23="Hospitalisation","Hospitalization",IF(D23="Medical Emerg.","Medical Emergency",IF(D23="Property dmg","Property Damage",IF(D23="Vehicle dmg","Vehicle Damage",D23)))) -> Property Damage | T23: =IF(J23>K23,"SLA Breach","Within SLA") -> SLA Breach | U23: =IF(J23>K23,J23-K23,0) -> 6
A24: CLM000023 | B24: CUST02219 | C24: POL01446 | D24: Baggage Loss | E24: South | F24: 30935.87 | G24: 45831 | I24: Under Review | J24: 21 | K24: 7 | L24: AGT029 | M24: Travel | N24: Manual Review | O24: =COUNTIF($A:$A,A24) -> 1 | P24: =IF(F24="","Missing Amount","Valid") -> Valid | Q24: =_xlfn.XLOOKUP(B24,Customers!$A:$A,Customers!$C:$C,"Not Found") -> East | R24: =IF(E24="",Q24,E24) -> South | S24: =IF(D24="Hospitalisation","Hospitalization",IF(D24="Medical Emerg.","Medical Emergency",IF(D24="Property dmg","Property Damage",IF(D24="Vehicle dmg","Vehicle Damage",D24)))) -> Baggage Loss | T24: =IF(J24>K24,"SLA Breach","Within SLA") -> SLA Breach | U24: =IF(J24>K24,J24-K24,0) -> 14
A25: CLM000024 | B25: CUST02143 | C25: POL00431 | D25: Baggage Loss | E25: South | F25: 27056.64 | G25: 45910 | H25: 45913 | I25: Settled | J25: 3 | K25: 7 | L25: AGT069 | M25: Travel | N25: Standard | O25: =COUNTIF($A:$A,A25) -> 1 | P25: =IF(F25="","Missing Amount","Valid") -> Valid | Q25: =_xlfn.XLOOKUP(B25,Customers!$A:$A,Customers!$C:$C,"Not Found") -> East | R25: =IF(E25="",Q25,E25) -> South | S25: =IF(D25="Hospitalisation","Hospitalization",IF(D25="Medical Emerg.","Medical Emergency",IF(D25="Property dmg","Property Damage",IF(D25="Vehicle dmg","Vehicle Damage",D25)))) -> Baggage Loss | T25: =IF(J25>K25,"SLA Breach","Within SLA") -> Within SLA | U25: =IF(J25>K25,J25-K25,0) -> 0
A26: CLM000025 | B26: CUST01896 | C26: POL02875 | D26: Death Benefit | E26: South | F26: 917601.23 | G26: 45783 | I26: Pending | J26: 25 | K26: 20 | L26: AGT016 | M26: Life | N26: Fraud Review | O26: =COUNTIF($A:$A,A26) -> 1 | P26: =IF(F26="","Missing Amount","Valid") -> Valid | Q26: =_xlfn.XLOOKUP(B26,Customers!$A:$A,Customers!$C:$C,"Not Found") -> South | R26: =IF(E26="",Q26,E26) -> South | S26: =IF(D26="Hospitalisation","Hospitalization",IF(D26="Medical Emerg.","Medical Emergency",IF(D26="Property dmg","Property Damage",IF(D26="Vehicle dmg","Vehicle Damage",D26)))) -> Death Benefit | T26: =IF(J26>K26,"SLA Breach","Within SLA") -> SLA Breach | U26: =IF(J26>K26,J26-K26,0) -> 5
A27: CLM000026 | B27: CUST01337 | C27: POL01161 | D27: Theft | E27: East | F27: 307261.32 | G27: 45796 | I27: Pending | J27: 25 | K27: 12 | L27: AGT061 | M27: Home | N27: Fraud Review | O27: =COUNTIF($A:$A,A27) -> 1 | P27: =IF(F27="","Missing Amount","Valid") -> Valid | Q27: =_xlfn.XLOOKUP(B27,Customers!$A:$A,Customers!$C:$C,"Not Found") -> West | R27: =IF(E27="",Q27,E27) -> East | S27: =IF(D27="Hospitalisation","Hospitalization",IF(D27="Medical Emerg.","Medical Emergency",IF(D27="Property dmg","Property Damage",IF(D27="Vehicle dmg","Vehicle Damage",D27)))) -> Theft | T27: =IF(J27>K27,"SLA Breach","Within SLA") -> SLA Breach | U27: =IF(J27>K27,J27-K27,0) -> 13
A28: CLM000027 | B28: CUST01165 | C28: POL02612 | D28: Accident | E28: North | F28: 102362.34 | G28: 45706 | I28: Pending | J28: 6 | K28: 10 | L28: AGT029 | M28: Motor | N28: Standard | O28: =COUNTIF($A:$A,A28) -> 1 | P28: =IF(F28="","Missing Amount","Valid") -> Valid | Q28: =_xlfn.XLOOKUP(B28,Customers!$A:$A,Customers!$C:$C,"Not Found") -> South | R28: =IF(E28="",Q28,E28) -> North | S28: =IF(D28="Hospitalisation","Hospitalization",IF(D28="Medical Emerg.","Medical Emergency",IF(D28="Property dmg","Property Damage",IF(D28="Vehicle dmg","Vehicle Damage",D28)))) -> Accident | T28: =IF(J28>K28,"SLA Breach","Within SLA") -> Within SLA | U28: =IF(J28>K28,J28-K28,0) -> 0
A29: CLM000028 | B29: CUST01648 | C29: POL01281 | D29: Hospitalization | E29: South | F29: 56581.21 | G29: 45853 | H29: 45865 | I29: Settled | J29: 12 | K29: 15 | L29: AGT076 | M29: Health | N29: Standard | O29: =COUNTIF($A:$A,A29) -> 1 | P29: =IF(F29="","Missing Amount","Valid") -> Valid | Q29: =_xlfn.XLOOKUP(B29,Customers!$A:$A,Customers!$C:$C,"Not Found") -> West | R29: =IF(E29="",Q29,E29) -> South | S29: =IF(D29="Hospitalisation","Hospitalization",IF(D29="Medical Emerg.","Medical Emergency",IF(D29="Property dmg","Property Damage",IF(D29="Vehicle dmg","Vehicle Damage",D29)))) -> Hospitalization | T29: =IF(J29>K29,"SLA Breach","Within SLA") -> Within SLA | U29: =IF(J29>K29,J29-K29,0) -> 0
A30: CLM000029 | B30: CUST00260 | C30: POL01511 | D30: Vehicle Damage | E30: South | F30: 11600.71 | G30: 45965 | H30: 45972 | I30: Settled | J30: 7 | K30: 10 | L30: AGT077 | M30: Motor | N30: Standard | O30: =COUNTIF($A:$A,A30) -> 1 | P30: =IF(F30="","Missing Amount","Valid") -> Valid | Q30: =_xlfn.XLOOKUP(B30,Customers!$A:$A,Customers!$C:$C,"Not Found") -> East | R30: =IF(E30="",Q30,E30) -> South | S30: =IF(D30="Hospitalisation","Hospitalization",IF(D30="Medical Emerg.","Medical Emergency",IF(D30="Property dmg","Property Damage",IF(D30="Vehicle dmg","Vehicle Damage",D30)))) -> Vehicle Damage | T30: =IF(J30>K30,"SLA Breach","Within SLA") -> Within SLA | U30: =IF(J30>K30,J30-K30,0) -> 0
A31: CLM000030 | B31: CUST01115 | C31: POL00359 | D31: Hospitalization | E31: South | F31: 37012.64 | G31: 45853 | H31: 45866 | I31: Settled | J31: 13 | K31: 15 | L31: AGT034 | M31: Health | N31: Manual Review | O31: =COUNTIF($A:$A,A31) -> 1 | P31: =IF(F31="","Missing Amount","Valid") -> Valid | Q31: =_xlfn.XLOOKUP(B31,Customers!$A:$A,Customers!$C:$C,"Not Found") -> East | R31: =IF(E31="",Q31,E31) -> South | S31: =IF(D31="Hospitalisation","Hospitalization",IF(D31="Medical Emerg.","Medical Emergency",IF(D31="Property dmg","Property Damage",IF(D31="Vehicle dmg","Vehicle Damage",D31)))) -> Hospitalization | T31: =IF(J31>K31,"SLA Breach","Within SLA") -> Within SLA | U31: =IF(J31>K31,J31-K31,0) -> 0
A32: CLM000031 | B32: CUST00862 | C32: POL02166 | D32: Property Damage | E32: West | F32: 40326.41 | G32: 45957 | H32: 45970 | I32: Settled | J32: 13 | K32: 12 | L32: AGT063 | M32: Home | N32: Fast Track | O32: =COUNTIF($A:$A,A32) -> 1 | P32: =IF(F32="","Missing Amount","Valid") -> Valid | Q32: =_xlfn.XLOOKUP(B32,Customers!$A:$A,Customers!$C:$C,"Not Found") -> South | R32: =IF(E32="",Q32,E32) -> West | S32: =IF(D32="Hospitalisation","Hospitalization",IF(D32="Medical Emerg.","Medical Emergency",IF(D32="Property dmg","Property Damage",IF(D32="Vehicle dmg","Vehicle Damage",D32)))) -> Property Damage | T32: =IF(J32>K32,"SLA Breach","Within SLA") -> SLA Breach | U32: =IF(J32>K32,J32-K32,0) -> 1
A33: CLM000032 | B33: CUST00688 | C33: POL00192 | D33: Maturity | E33: South | F33: 288302.89 | G33: 45660 | H33: 45688 | I33: Settled | J33: 28 | K33: 20 | L33: AGT074 | M33: Life | N33: Manual Review | O33: =COUNTIF($A:$A,A33) -> 1 | P33: =IF(F33="","Missing Amount","Valid") -> Valid | Q33: =_xlfn.XLOOKUP(B33,Customers!$A:$A,Customers!$C:$C,"Not Found") -> Central | R33: =IF(E33="",Q33,E33) -> South | S33: =IF(D33="Hospitalisation","Hospitalization",IF(D33="Medical Emerg.","Medical Emergency",IF(D33="Property dmg","Property Damage",IF(D33="Vehicle dmg","Vehicle Damage",D33)))) -> Maturity | T33: =IF(J33>K33,"SLA Breach","Within SLA") -> SLA Breach | U33: =IF(J33>K33,J33-K33,0) -> 8
A34: CLM000033 | B34: CUST01245 | C34: POL02394 | D34: Accident | E34: North | F34: 119585.73 | G34: 45904 | H34: 45934 | I34: Settled | J34: 30 | K34: 10 | L34: AGT049 | M34: Motor | N34: Fraud Review | O34: =COUNTIF($A:$A,A34) -> 1 | P34: =IF(F34="","Missing Amount","Valid") -> Valid | Q34: =_xlfn.XLOOKUP(B34,Customers!$A:$A,Customers!$C:$C,"Not Found") -> North | R34: =IF(E34="",Q34,E34) -> North | S34: =IF(D34="Hospitalisation","Hospitalization",IF(D34="Medical Emerg.","Medical Emergency",IF(D34="Property dmg","Property Damage",IF(D34="Vehicle dmg","Vehicle Damage",D34)))) -> Accident | T34: =IF(J34>K34,"SLA Breach","Within SLA") -> SLA Breach | U34: =IF(J34>K34,J34-K34,0) -> 20
A35: CLM000034 | B35: CUST00978 | C35: POL02822 | D35: Accident | E35: Central | F35: 234785.03 | G35: 45661 | I35: Under Review | J35: 14 | K35: 10 | L35: AGT072 | M35: Motor | N35: Manual Review | O35: =COUNTIF($A:$A,A35) -> 1 | P35: =IF(F35="","Missing Amount","Valid") -> Valid | Q35: =_xlfn.XLOOKUP(B35,Customers!$A:$A,Customers!$C:$C,"Not Found") -> Central | R35: =IF(E35="",Q35,E35) -> Central | S35: =IF(D35="Hospitalisation","Hospitalization",IF(D35="Medical Emerg.","Medical Emergency",IF(D35="Property dmg","Property Damage",IF(D35="Vehicle dmg","Vehicle Damage",D35)))) -> Accident | T35: =IF(J35>K35,"SLA Breach","Within SLA") -> SLA Breach | U35: =IF(J35>K35,J35-K35,0) -> 4
A36: CLM000035 | B36: CUST02199 | C36: POL01158 | D36: Accident | E36: South | F36: 148745.03 | G36: 45801 | H36: 45814 | I36: Settled | J36: 13 | K36: 10 | L36: AGT055 | M36: Motor | N36: Standard | O36: =COUNTIF($A:$A,A36) -> 1 | P36: =IF(F36="","Missing Amount","Valid") -> Valid | Q36: =_xlfn.XLOOKUP(B36,Customers!$A:$A,Customers!$C:$C,"Not Found") -> East | R36: =IF(E36="",Q36,E36) -> South | S36: =IF(D36="Hospitalisation","Hospitalization",IF(D36="Medical Emerg.","Medical Emergency",IF(D36="Property dmg","Property Damage",IF(D36="Vehicle dmg","Vehicle Damage",D36)))) -> Accident | T36: =IF(J36>K36,"SLA Breach","Within SLA") -> SLA Breach | U36: =IF(J36>K36,J36-K36,0) -> 3
A37: CLM000036 | B37: CUST01363 | C37: POL02841 | D37: Trip Cancellation | E37: North | F37: 18913.75 | G37: 45815 | H37: 45817 | I37: Settled | J37: 2 | K37: 7 | L37: AGT002 | M37: Travel | N37: Fast Track | O37: =COUNTIF($A:$A,A37) -> 1 | P37: =IF(F37="","Missing Amount","Valid") -> Valid | Q37: =_xlfn.XLOOKUP(B37,Customers!$A:$A,Customers!$C:$C,"Not Found") -> West | R37: =IF(E37="",Q37,E37) -> North | S37: =IF(D37="Hospitalisation","Hospitalization",IF(D37="Medical Emerg.","Medical Emergency",IF(D37="Property dmg","Property Damage",IF(D37="Vehicle dmg","Vehicle Damage",D37)))) -> Trip Cancellation | T37: =IF(J37>K37,"SLA Breach","Within SLA") -> Within SLA | U37: =IF(J37>K37,J37-K37,0) -> 0
A38: CLM000037 | B38: CUST02342 | C38: POL02237 | D38: Disability | E38: West | F38: 353844.62 | G38: 45814 | H38: 45830 | I38: Settled | J38: 16 | K38: 20 | L38: AGT049 | M38: Life | N38: Standard | O38: =COUNTIF($A:$A,A38) -> 1 | P38: =IF(F38="","Missing Amount","Valid") -> Valid | Q38: =_xlfn.XLOOKUP(B38,Customers!$A:$A,Customers!$C:$C,"Not Found") -> South | R38: =IF(E38="",Q38,E38) -> West | S38: =IF(D38="Hospitalisation","Hospitalization",IF(D38="Medical Emerg.","Medical Emergency",IF(D38="Property dmg","Property Damage",IF(D38="Vehicle dmg","Vehicle Damage",D38)))) -> Disability | T38: =IF(J38>K38,"SLA Breach","Within SLA") -> Within SLA | U38: =IF(J38>K38,J38-K38,0) -> 0
A39: CLM000038 | B39: CUST00238 | C39: POL00009 | D39: Vehicle Damage | E39: West | F39: 84427.63 | G39: 45844 | H39: 45852 | I39: Settled | J39: 8 | K39: 10 | L39: AGT020 | M39: Motor | N39: Standard | O39: =COUNTIF($A:$A,A39) -> 1 | P39: =IF(F39="","Missing Amount","Valid") -> Valid | Q39: =_xlfn.XLOOKUP(B39,Customers!$A:$A,Customers!$C:$C,"Not Found") -> East | R39: =IF(E39="",Q39,E39) -> West | S39: =IF(D39="Hospitalisation","Hospitalization",IF(D39="Medical Emerg.","Medical Emergency",IF(D39="Property dmg","Property Damage",IF(D39="Vehicle dmg","Vehicle Damage",D39)))) -> Vehicle Damage | T39: =IF(J39>K39,"SLA Breach","Within SLA") -> Within SLA | U39: =IF(J39>K39,J39-K39,0) -> 0
A40: CLM000039 | B40: CUST01945 | C40: POL00650 | D40: Disability | E40: Central | F40: 108866.96 | G40: 45914 | H40: 45929 | I40: Settled | J40: 15 | K40: 20 | L40: AGT048 | M40: Life | N40: Standard | O40: =COUNTIF($A:$A,A40) -> 1 | P40: =IF(F40="","Missing Amount","Valid") -> Valid | Q40: =_xlfn.XLOOKUP(B40,Customers!$A:$A,Customers!$C:$C,"Not Found") -> North | R40: =IF(E40="",Q40,E40) -> Central | S40: =IF(D40="Hospitalisation","Hospitalization",IF(D40="Medical Emerg.","Medical Emergency",IF(D40="Property dmg","Property Damage",IF(D40="Vehicle dmg","Vehicle Damage",D40)))) -> Disability | T40: =IF(J40>K40,"SLA Breach","Within SLA") -> Within SLA | U40: =IF(J40>K40,J40-K40,0) -> 0
...

Sheet Customers
A1: Customer_ID | B1: Customer_Segment | C1: Customer_Region | D1: Customer_Tenure_Years
A2: CUST00001 | B2: Affluent | C2: North | D2: 7
A3: CUST00002 | B3: Retail | C3: West | D3: 5
A4: CUST00003 | B4: Affluent | C4: Central | D4: 11
A5: CUST00004 | B5: Retail | C5: West | D5: 14
A6: CUST00005 | B6: Retail | C6: South | D6: 6
A7: CUST00006 | B7: Corporate | C7: North | D7: 16
A8: CUST00007 | B8: Affluent | C8: Central | D8: 13
A9: CUST00008 | B9: Affluent | C9: Central | D9: 4
A10: CUST00009 | B10: Retail | C10: East | D10: 19
A11: CUST00010 | B11: Retail | C11: West | D11: 1
A12: CUST00011 | B12: Retail | C12: East | D12: 14
A13: CUST00012 | B13: Corporate | C13: South | D13: 9
... A2501: CUST02500 | B2501: Retail | C2501: East | D2501: 8

Sheet Excel_Analysis
A1: Metric | B1: Value
A2: Total Claims | B2: =COUNTA(claims_raw!A:A)-1 -> 8000
A3: SLA Breach Claims | B3: =COUNTIFS(claims_raw!T:T,"SLA Breach") -> 4025
A4: Pending Claims | B4: =COUNTIFS(claims_raw!I:I,"Pending") -> 1125
A5: Settled Claims | B5: =COUNTIFS(claims_raw!I:I,"Settled") -> 5543
A6: Total Claim Amount | B6: =SUMIFS(claims_raw!F:F,claims_raw!P:P,"Valid") -> 1.0953208e+09
A10: Region | B10: Total Claims | C10: SLA Breaches | D10: Breach Rate
A11: North | B11: =COUNTIFS(claims_raw!R:R,A11) -> 1718 | C11: =COUNTIFS(claims_raw!R:R,A11,claims_raw!T:T,"SLA Breach") -> 823 | D11: =C11/B11 -> 0.4790454
A12: South | B12: =COUNTIFS(claims_raw!R:R,A12) -> 1763 | C12: =COUNTIFS(claims_raw!R:R,A12,claims_raw!T:T,"SLA Breach") -> 738 | D12: =C12/B12 -> 0.41860465
A13: East | B13: =COUNTIFS(claims_raw!R:R,A13) -> 1459 | C13: =COUNTIFS(claims_raw!R:R,A13,claims_raw!T:T,"SLA Breach") -> 977 | D13: =C13/B13 -> 0.66963674
A14: West | B14: =COUNTIFS(claims_raw!R:R,A14) -> 1872 | C14: =COUNTIFS(claims_raw!R:R,A14,claims_raw!T:T,"SLA Breach") -> 792 | D14: =C14/B14 -> 0.42307692
A15: Central | B15: =COUNTIFS(claims_raw!R:R,A15) -> 1188 | C15: =COUNTIFS(claims_raw!R:R,A15,claims_raw!T:T,"SLA Breach") -> 695 | D15: =C15/B15 -> 0.58501684
A17: Workflow | B17: Average Processing Days | C17: SLA Breach Claims | D17: SLA Breach Rate
A18: Standard | B18: =AVERAGEIFS(claims_raw!J:J,claims_raw!N:N,A18) -> 11.94783 | C18: =COUNTIFS(claims_raw!N:N,A18,claims_raw!T:T,"SLA Breach") -> 1569 | D18: =COUNTIFS(claims_raw!N:N,A18,claims_raw!T:T,"SLA Breach")/COUNTIFS(claims_raw!N:N,A18) -> 0.36218837
A19: Manual Review | B19: =AVERAGEIFS(claims_raw!J:J,claims_raw!N:N,A19) -> 19.121696 | C19: =COUNTIFS(claims_raw!N:N,A19,claims_raw!T:T,"SLA Breach") -> 1457 | D19: =COUNTIFS(claims_raw!N:N,A19,claims_raw!T:T,"SLA Breach")/COUNTIFS(claims_raw!N:N,A19) -> 0.89551321
A20: Fraud Review | B20: =AVERAGEIFS(claims_raw!J:J,claims_raw!N:N,A20) -> 25.981572 | C20: =COUNTIFS(claims_raw!N:N,A20,claims_raw!T:T,"SLA Breach") -> 811 | D20: =COUNTIFS(claims_raw!N:N,A20,claims_raw!T:T,"SLA Breach")/COUNTIFS(claims_raw!N:N,A20) -> 0.9963145
A21: Fast Track | B21: =AVERAGEIFS(claims_raw!J:J,claims_raw!N:N,A21) -> 8.99185 | C21: =COUNTIFS(claims_raw!N:N,A21,claims_raw!T:T,"SLA Breach") -> 188 | D21: =COUNTIFS(claims_raw!N:N,A21,claims_raw!T:T,"SLA Breach")/COUNTIFS(claims_raw!N:N,A21) -> 0.15321923
A23: Policy Type | B23: Total Claim Amount
A24: Health | B24: =SUMIFS(claims_raw!F:F,claims_raw!M:M,A24,claims_raw!P:P,"Valid") -> 2.3729068e+08
A25: Motor | B25: =SUMIFS(claims_raw!F:F,claims_raw!M:M,A25,claims_raw!P:P,"Valid") -> 1.816592e+08
A26: Travel | B26: =SUMIFS(claims_raw!F:F,claims_raw!M:M,A26,claims_raw!P:P,"Valid") -> 37744577
A27: Home | B27: =SUMIFS(claims_raw!F:F,claims_raw!M:M,A27,claims_raw!P:P,"Valid") -> 1.6686288e+08
A28: Life | B28: =SUMIFS(claims_raw!F:F,claims_raw!M:M,A28,claims_raw!P:P,"Valid") -> 4.717635e+08
